<?xml version="1.0" encoding="utf-8"?>
<robot xmlns:xacro="http://www.ros.org/wiki/xacro" name="fork_end_effector">
  <xacro:macro name="fork_end_effector" params="connected_to:='' ns:='' rpy:='0 0 0' xyz:='0 0 0'">
    <xacro:unless value="${connected_to == ''}">
      <joint name="${ns}_fork_joint" type="fixed">
        <parent link="${connected_to}"/>
        <child link="${ns}_forkbase"/>
        <origin xyz="${xyz}" rpy="${rpy}"/>
      </joint>
    </xacro:unless>

    <xacro:if value="${connected_to == ''}">
        <!-- Create a dummy link -->
        <link name="${ns}_dummy_link" />

        <joint name="${ns}_dummy_joint" type="fixed">
            <parent link="${ns}_dummy_link"/>
            <child link="${ns}_forkbase"/>
        </joint>
    </xacro:if>

    <link
        name="${ns}_forkbase">
        <inertial>
        <origin
            xyz="0.0061112 0.00063068 0.019952"
            rpy="0 0 0" />
        <mass
            value="0.097534" />
        <inertia
            ixx="3.6765E-05"
            ixy="4.6072E-08"
            ixz="-2.3579E-07"
            iyy="2.7292E-05"
            iyz="-6.4287E-09"
            izz="3.9785E-05" />
        </inertial>
        <visual>
        <origin
            xyz="0 0 0"
            rpy="0 0 0" />
        <geometry>
            <mesh
            filename="package://fork_end_effector/meshes/base_link.STL" />
        </geometry>
        <material
            name="">
            <color
            rgba="0.75294 1 0.75294 1" />
        </material>
        </visual>
        <collision>
        <origin
            xyz="0 0 0"
            rpy="0 0 0" />
        <geometry>
            <mesh
            filename="package://fork_end_effector/meshes/base_link.STL" />
        </geometry>
        </collision>
    </link>
    
    <!-- Camera Data (may need to update rotation) -->
    <joint name="${ns}_forkcameraoffset" type="fixed">
        <parent link="${ns}_forkbase"/>
        <child  link="${ns}_forkcamera"/>
        <origin xyz="0.0149 0 0.0485" rpy="0 0 0"/>
    </joint>

    <link name="${ns}_forkcamera"/>
    
    <link
        name="${ns}_forkpitch">
        <inertial>
        <origin
            xyz="0.027347 0.0056419 -0.00036659"
            rpy="0 0 0" />
        <mass
            value="0.019491" />
        <inertia
            ixx="2.528E-06"
            ixy="2.6211E-09"
            ixz="-3.5082E-09"
            iyy="8.9887E-07"
            iyz="-1.4142E-09"
            izz="2.2752E-06" />
        </inertial>
        <visual>
        <origin
            xyz="0 0 0"
            rpy="0 0 0" />
        <geometry>
            <mesh
            filename="package://fork_end_effector/meshes/pitch_link.STL" />
        </geometry>
        <material
            name="">
            <color
            rgba="1 0.50196 0.50196 1" />
        </material>
        </visual>
        <collision>
        <origin
            xyz="0 0 0"
            rpy="0 0 0" />
        <geometry>
            <mesh
            filename="package://fork_end_effector/meshes/pitch_link.STL" />
        </geometry>
        </collision>
    </link>
    <joint
        name="${ns}_forkpitch_joint"
        type="revolute">
        <origin
        xyz="0.0395 0 0"
        rpy="0 0 0" />
        <parent
        link="${ns}_forkbase" />
        <child
        link="${ns}_forkpitch" />
        <axis
        xyz="0 -1 0" />
        <limit
        lower="${-pi/2}"
        upper="${pi/2}"
        effort="0.93"
        velocity="8.4" />
    </joint>
    <link
        name="${ns}_forkroll">
        <inertial>
        <origin
            xyz="0.011976 -0.00049403 -0.00081409"
            rpy="0 0 0" />
        <mass
            value="0.072775" />
        <inertia
            ixx="1.821E-05"
            ixy="-4.1084E-09"
            ixz="-1.448E-07"
            iyy="1.062E-05"
            iyz="-1.5136E-09"
            izz="1.0557E-05" />
        </inertial>
        <visual>
        <origin
            xyz="0 0 0"
            rpy="0 0 0" />
        <geometry>
            <mesh
            filename="package://fork_end_effector/meshes/roll_link.STL" />
        </geometry>
        <material
            name="">
            <color
            rgba="1 1 1 1" />
        </material>
        </visual>
        <collision>
        <origin
            xyz="0 0 0"
            rpy="0 0 0" />
        <geometry>
            <mesh
            filename="package://fork_end_effector/meshes/roll_link.STL" />
        </geometry>
        </collision>
    </link>
    <joint
        name="${ns}_forkroll_joint"
        type="continuous">
        <origin
        xyz="0.045083 0 0"
        rpy="0 0 0" />
        <parent
        link="${ns}_forkpitch" />
        <child
        link="${ns}_forkroll" />
        <axis
        xyz="1 0 0" />
        <limit
        effort="0.93"
        velocity="8.4" />
    </joint>
  </xacro:macro>
</robot>
